<?xml version="1.0"?>
<robot name="final_robot">
    <material name="blue">
        <color rgba="0.0 0.0 1.0 1.0"/>
    </material>
    <material name="black">
        <color rgba="0.0 0.0 0.0 1.0"/>
    </material>
    <material name="white">
        <color rgba="1.0 1.0 1.0 1.0"/>
    </material>
	<material name="Orange">
	<color rgba="1.0 0.423529411765 0.0392156862745 1.0"/>
	</material>
    <link name="world"/>
	
    <link name="base_link">
        <visual>
            <origin xyz="0.0 0.0 0.2" rpy="0.0 0.0 0.0"/>
            <geometry>
                <cylinder length="0.5" radius="0.1"/>
            </geometry>
            <material name="black"/>
        </visual>
    </link>
    <joint name="base_joint" type="fixed">
        <parent link="world"/>
        <child link="base_link"/>
    </joint>

    <link name="arm1">
        <visual>
            <origin xyz="0.0 -0.2 -0.2" rpy="1.5708 0.0 0.0"/>
            <geometry>
				<cylinder length="0.3" radius="0.05"/>
            </geometry>
            <material name="Orange"/>
        </visual>
    </link>
    <joint name="arm1_joint" type="revolute">
        <origin xyz="0.0 0.0 0.7" rpy="0.0 0.0 0.0"/>
        <parent link="base_link"/>
        <child link="arm1"/>
        <axis xyz="0.0 0.0 1.0"/>
        <limit lower="0.0" upper="1.0" effort="1000.0" velocity="1000.0"/>
    </joint>

    <link name="revolute_link">
        <visual>
            <origin xyz="0.0 0.60 -0.1" rpy="0.0 0.0 0.0"/>
            <geometry>
                <cylinder length="0.3" radius="0.05"/>
            </geometry>
            <material name="blue"/>
        </visual>
    </link>
    <joint name="revolute_joint" type="revolute">
		<origin xyz="0.0 -1.0 0.0" rpy="0.0 0.0 0.0"/>
        <parent link="arm1"/>
        <child link="revolute_link"/>
		<axis xyz="0.0 0.0 1.0"/>
        <limit lower="0.0" upper="1.0" effort="1000.0" velocity="1000.0"/>
	</joint>

    <link name="arm2">
        <visual>
            <origin xyz="0.0 0.5 -0.2" rpy="0.0 0.0 0.0"/>
            <geometry>
                <box size="0.1 0.3 0.1"/>
            </geometry>
            <material name="black"/>
        </visual>
    </link>
    <joint name="arm2_joint" type="prismatic">
        <origin xyz="0.0 -0.1 0.2" rpy="0.0 0.0 0.0"/>
        <parent link="revolute_link"/>
        <child link="arm2"/>
        <axis xyz="0.0 0.0 1.0"/>
        <limit lower="-0.2" upper="0.0" effort="1000.0" velocity="1000.0"/>
	</joint>

</robot>
